<?xml version="1.0"?>
<!--
  Simple Humanoid Robot URDF

  This URDF defines a basic humanoid robot with:
  - Torso (base)
  - Head
  - Two arms (shoulder, elbow, wrist)
  - Two legs (hip, knee, ankle)

  All dimensions are approximate for educational purposes.
-->
<robot name="simple_humanoid">

  <!-- ==================== MATERIALS ==================== -->
  <material name="blue">
    <color rgba="0.2 0.4 0.8 1.0"/>
  </material>

  <material name="gray">
    <color rgba="0.5 0.5 0.5 1.0"/>
  </material>

  <material name="orange">
    <color rgba="1.0 0.5 0.0 1.0"/>
  </material>

  <material name="white">
    <color rgba="0.9 0.9 0.9 1.0"/>
  </material>

  <!-- ==================== TORSO (BASE LINK) ==================== -->
  <link name="base_link">
    <visual>
      <geometry>
        <box size="0.3 0.2 0.4"/>
      </geometry>
      <origin xyz="0 0 0" rpy="0 0 0"/>
      <material name="blue"/>
    </visual>
    <collision>
      <geometry>
        <box size="0.3 0.2 0.4"/>
      </geometry>
      <origin xyz="0 0 0" rpy="0 0 0"/>
    </collision>
    <inertial>
      <mass value="10.0"/>
      <inertia ixx="0.1" ixy="0" ixz="0" iyy="0.1" iyz="0" izz="0.05"/>
    </inertial>
  </link>

  <!-- ==================== HEAD ==================== -->
  <link name="head">
    <visual>
      <geometry>
        <sphere radius="0.1"/>
      </geometry>
      <origin xyz="0 0 0" rpy="0 0 0"/>
      <material name="white"/>
    </visual>
    <collision>
      <geometry>
        <sphere radius="0.1"/>
      </geometry>
    </collision>
    <inertial>
      <mass value="1.0"/>
      <inertia ixx="0.004" ixy="0" ixz="0" iyy="0.004" iyz="0" izz="0.004"/>
    </inertial>
  </link>

  <joint name="head_joint" type="revolute">
    <parent link="base_link"/>
    <child link="head"/>
    <origin xyz="0 0 0.3" rpy="0 0 0"/>
    <axis xyz="0 0 1"/>
    <limit lower="-1.57" upper="1.57" effort="10" velocity="1.0"/>
  </joint>

  <!-- ==================== LEFT ARM ==================== -->
  <link name="left_shoulder">
    <visual>
      <geometry>
        <sphere radius="0.05"/>
      </geometry>
      <material name="gray"/>
    </visual>
    <collision>
      <geometry>
        <sphere radius="0.05"/>
      </geometry>
    </collision>
    <inertial>
      <mass value="0.5"/>
      <inertia ixx="0.001" ixy="0" ixz="0" iyy="0.001" iyz="0" izz="0.001"/>
    </inertial>
  </link>

  <joint name="left_shoulder_joint" type="revolute">
    <parent link="base_link"/>
    <child link="left_shoulder"/>
    <origin xyz="0 0.15 0.15" rpy="0 0 0"/>
    <axis xyz="0 1 0"/>
    <limit lower="-3.14" upper="3.14" effort="50" velocity="2.0"/>
  </joint>

  <link name="left_upper_arm">
    <visual>
      <geometry>
        <cylinder radius="0.03" length="0.2"/>
      </geometry>
      <origin xyz="0 0.1 0" rpy="1.5708 0 0"/>
      <material name="blue"/>
    </visual>
    <collision>
      <geometry>
        <cylinder radius="0.03" length="0.2"/>
      </geometry>
      <origin xyz="0 0.1 0" rpy="1.5708 0 0"/>
    </collision>
    <inertial>
      <mass value="1.0"/>
      <inertia ixx="0.003" ixy="0" ixz="0" iyy="0.003" iyz="0" izz="0.001"/>
    </inertial>
  </link>

  <joint name="left_upper_arm_joint" type="fixed">
    <parent link="left_shoulder"/>
    <child link="left_upper_arm"/>
    <origin xyz="0 0 0" rpy="0 0 0"/>
  </joint>

  <link name="left_forearm">
    <visual>
      <geometry>
        <cylinder radius="0.025" length="0.18"/>
      </geometry>
      <origin xyz="0 0.09 0" rpy="1.5708 0 0"/>
      <material name="gray"/>
    </visual>
    <collision>
      <geometry>
        <cylinder radius="0.025" length="0.18"/>
      </geometry>
      <origin xyz="0 0.09 0" rpy="1.5708 0 0"/>
    </collision>
    <inertial>
      <mass value="0.8"/>
      <inertia ixx="0.002" ixy="0" ixz="0" iyy="0.002" iyz="0" izz="0.001"/>
    </inertial>
  </link>

  <joint name="left_elbow_joint" type="revolute">
    <parent link="left_upper_arm"/>
    <child link="left_forearm"/>
    <origin xyz="0 0.2 0" rpy="0 0 0"/>
    <axis xyz="1 0 0"/>
    <limit lower="0" upper="2.5" effort="30" velocity="2.0"/>
  </joint>

  <link name="left_hand">
    <visual>
      <geometry>
        <box size="0.04 0.08 0.02"/>
      </geometry>
      <material name="orange"/>
    </visual>
    <collision>
      <geometry>
        <box size="0.04 0.08 0.02"/>
      </geometry>
    </collision>
    <inertial>
      <mass value="0.3"/>
      <inertia ixx="0.0002" ixy="0" ixz="0" iyy="0.0002" iyz="0" izz="0.0001"/>
    </inertial>
  </link>

  <joint name="left_wrist_joint" type="revolute">
    <parent link="left_forearm"/>
    <child link="left_hand"/>
    <origin xyz="0 0.18 0" rpy="0 0 0"/>
    <axis xyz="0 1 0"/>
    <limit lower="-1.0" upper="1.0" effort="10" velocity="2.0"/>
  </joint>

  <!-- ==================== RIGHT ARM ==================== -->
  <link name="right_shoulder">
    <visual>
      <geometry>
        <sphere radius="0.05"/>
      </geometry>
      <material name="gray"/>
    </visual>
    <collision>
      <geometry>
        <sphere radius="0.05"/>
      </geometry>
    </collision>
    <inertial>
      <mass value="0.5"/>
      <inertia ixx="0.001" ixy="0" ixz="0" iyy="0.001" iyz="0" izz="0.001"/>
    </inertial>
  </link>

  <joint name="right_shoulder_joint" type="revolute">
    <parent link="base_link"/>
    <child link="right_shoulder"/>
    <origin xyz="0 -0.15 0.15" rpy="0 0 0"/>
    <axis xyz="0 1 0"/>
    <limit lower="-3.14" upper="3.14" effort="50" velocity="2.0"/>
  </joint>

  <link name="right_upper_arm">
    <visual>
      <geometry>
        <cylinder radius="0.03" length="0.2"/>
      </geometry>
      <origin xyz="0 -0.1 0" rpy="1.5708 0 0"/>
      <material name="blue"/>
    </visual>
    <collision>
      <geometry>
        <cylinder radius="0.03" length="0.2"/>
      </geometry>
      <origin xyz="0 -0.1 0" rpy="1.5708 0 0"/>
    </collision>
    <inertial>
      <mass value="1.0"/>
      <inertia ixx="0.003" ixy="0" ixz="0" iyy="0.003" iyz="0" izz="0.001"/>
    </inertial>
  </link>

  <joint name="right_upper_arm_joint" type="fixed">
    <parent link="right_shoulder"/>
    <child link="right_upper_arm"/>
    <origin xyz="0 0 0" rpy="0 0 0"/>
  </joint>

  <link name="right_forearm">
    <visual>
      <geometry>
        <cylinder radius="0.025" length="0.18"/>
      </geometry>
      <origin xyz="0 -0.09 0" rpy="1.5708 0 0"/>
      <material name="gray"/>
    </visual>
    <collision>
      <geometry>
        <cylinder radius="0.025" length="0.18"/>
      </geometry>
      <origin xyz="0 -0.09 0" rpy="1.5708 0 0"/>
    </collision>
    <inertial>
      <mass value="0.8"/>
      <inertia ixx="0.002" ixy="0" ixz="0" iyy="0.002" iyz="0" izz="0.001"/>
    </inertial>
  </link>

  <joint name="right_elbow_joint" type="revolute">
    <parent link="right_upper_arm"/>
    <child link="right_forearm"/>
    <origin xyz="0 -0.2 0" rpy="0 0 0"/>
    <axis xyz="1 0 0"/>
    <limit lower="0" upper="2.5" effort="30" velocity="2.0"/>
  </joint>

  <link name="right_hand">
    <visual>
      <geometry>
        <box size="0.04 0.08 0.02"/>
      </geometry>
      <material name="orange"/>
    </visual>
    <collision>
      <geometry>
        <box size="0.04 0.08 0.02"/>
      </geometry>
    </collision>
    <inertial>
      <mass value="0.3"/>
      <inertia ixx="0.0002" ixy="0" ixz="0" iyy="0.0002" iyz="0" izz="0.0001"/>
    </inertial>
  </link>

  <joint name="right_wrist_joint" type="revolute">
    <parent link="right_forearm"/>
    <child link="right_hand"/>
    <origin xyz="0 -0.18 0" rpy="0 0 0"/>
    <axis xyz="0 1 0"/>
    <limit lower="-1.0" upper="1.0" effort="10" velocity="2.0"/>
  </joint>

  <!-- ==================== LEFT LEG ==================== -->
  <link name="left_hip">
    <visual>
      <geometry>
        <sphere radius="0.05"/>
      </geometry>
      <material name="gray"/>
    </visual>
    <collision>
      <geometry>
        <sphere radius="0.05"/>
      </geometry>
    </collision>
    <inertial>
      <mass value="0.5"/>
      <inertia ixx="0.001" ixy="0" ixz="0" iyy="0.001" iyz="0" izz="0.001"/>
    </inertial>
  </link>

  <joint name="left_hip_joint" type="revolute">
    <parent link="base_link"/>
    <child link="left_hip"/>
    <origin xyz="0 0.1 -0.2" rpy="0 0 0"/>
    <axis xyz="0 1 0"/>
    <limit lower="-1.57" upper="1.57" effort="100" velocity="2.0"/>
  </joint>

  <link name="left_thigh">
    <visual>
      <geometry>
        <cylinder radius="0.04" length="0.3"/>
      </geometry>
      <origin xyz="0 0 -0.15" rpy="0 0 0"/>
      <material name="blue"/>
    </visual>
    <collision>
      <geometry>
        <cylinder radius="0.04" length="0.3"/>
      </geometry>
      <origin xyz="0 0 -0.15" rpy="0 0 0"/>
    </collision>
    <inertial>
      <mass value="2.0"/>
      <inertia ixx="0.02" ixy="0" ixz="0" iyy="0.02" iyz="0" izz="0.003"/>
    </inertial>
  </link>

  <joint name="left_thigh_joint" type="fixed">
    <parent link="left_hip"/>
    <child link="left_thigh"/>
    <origin xyz="0 0 0" rpy="0 0 0"/>
  </joint>

  <link name="left_shin">
    <visual>
      <geometry>
        <cylinder radius="0.035" length="0.28"/>
      </geometry>
      <origin xyz="0 0 -0.14" rpy="0 0 0"/>
      <material name="gray"/>
    </visual>
    <collision>
      <geometry>
        <cylinder radius="0.035" length="0.28"/>
      </geometry>
      <origin xyz="0 0 -0.14" rpy="0 0 0"/>
    </collision>
    <inertial>
      <mass value="1.5"/>
      <inertia ixx="0.015" ixy="0" ixz="0" iyy="0.015" iyz="0" izz="0.002"/>
    </inertial>
  </link>

  <joint name="left_knee_joint" type="revolute">
    <parent link="left_thigh"/>
    <child link="left_shin"/>
    <origin xyz="0 0 -0.3" rpy="0 0 0"/>
    <axis xyz="0 1 0"/>
    <limit lower="0" upper="2.5" effort="80" velocity="2.0"/>
  </joint>

  <link name="left_foot">
    <visual>
      <geometry>
        <box size="0.15 0.08 0.03"/>
      </geometry>
      <origin xyz="0.03 0 0" rpy="0 0 0"/>
      <material name="orange"/>
    </visual>
    <collision>
      <geometry>
        <box size="0.15 0.08 0.03"/>
      </geometry>
      <origin xyz="0.03 0 0" rpy="0 0 0"/>
    </collision>
    <inertial>
      <mass value="0.5"/>
      <inertia ixx="0.0003" ixy="0" ixz="0" iyy="0.001" iyz="0" izz="0.001"/>
    </inertial>
  </link>

  <joint name="left_ankle_joint" type="revolute">
    <parent link="left_shin"/>
    <child link="left_foot"/>
    <origin xyz="0 0 -0.28" rpy="0 0 0"/>
    <axis xyz="0 1 0"/>
    <limit lower="-0.5" upper="0.5" effort="50" velocity="2.0"/>
  </joint>

  <!-- ==================== RIGHT LEG ==================== -->
  <link name="right_hip">
    <visual>
      <geometry>
        <sphere radius="0.05"/>
      </geometry>
      <material name="gray"/>
    </visual>
    <collision>
      <geometry>
        <sphere radius="0.05"/>
      </geometry>
    </collision>
    <inertial>
      <mass value="0.5"/>
      <inertia ixx="0.001" ixy="0" ixz="0" iyy="0.001" iyz="0" izz="0.001"/>
    </inertial>
  </link>

  <joint name="right_hip_joint" type="revolute">
    <parent link="base_link"/>
    <child link="right_hip"/>
    <origin xyz="0 -0.1 -0.2" rpy="0 0 0"/>
    <axis xyz="0 1 0"/>
    <limit lower="-1.57" upper="1.57" effort="100" velocity="2.0"/>
  </joint>

  <link name="right_thigh">
    <visual>
      <geometry>
        <cylinder radius="0.04" length="0.3"/>
      </geometry>
      <origin xyz="0 0 -0.15" rpy="0 0 0"/>
      <material name="blue"/>
    </visual>
    <collision>
      <geometry>
        <cylinder radius="0.04" length="0.3"/>
      </geometry>
      <origin xyz="0 0 -0.15" rpy="0 0 0"/>
    </collision>
    <inertial>
      <mass value="2.0"/>
      <inertia ixx="0.02" ixy="0" ixz="0" iyy="0.02" iyz="0" izz="0.003"/>
    </inertial>
  </link>

  <joint name="right_thigh_joint" type="fixed">
    <parent link="right_hip"/>
    <child link="right_thigh"/>
    <origin xyz="0 0 0" rpy="0 0 0"/>
  </joint>

  <link name="right_shin">
    <visual>
      <geometry>
        <cylinder radius="0.035" length="0.28"/>
      </geometry>
      <origin xyz="0 0 -0.14" rpy="0 0 0"/>
      <material name="gray"/>
    </visual>
    <collision>
      <geometry>
        <cylinder radius="0.035" length="0.28"/>
      </geometry>
      <origin xyz="0 0 -0.14" rpy="0 0 0"/>
    </collision>
    <inertial>
      <mass value="1.5"/>
      <inertia ixx="0.015" ixy="0" ixz="0" iyy="0.015" iyz="0" izz="0.002"/>
    </inertial>
  </link>

  <joint name="right_knee_joint" type="revolute">
    <parent link="right_thigh"/>
    <child link="right_shin"/>
    <origin xyz="0 0 -0.3" rpy="0 0 0"/>
    <axis xyz="0 1 0"/>
    <limit lower="0" upper="2.5" effort="80" velocity="2.0"/>
  </joint>

  <link name="right_foot">
    <visual>
      <geometry>
        <box size="0.15 0.08 0.03"/>
      </geometry>
      <origin xyz="0.03 0 0" rpy="0 0 0"/>
      <material name="orange"/>
    </visual>
    <collision>
      <geometry>
        <box size="0.15 0.08 0.03"/>
      </geometry>
      <origin xyz="0.03 0 0" rpy="0 0 0"/>
    </collision>
    <inertial>
      <mass value="0.5"/>
      <inertia ixx="0.0003" ixy="0" ixz="0" iyy="0.001" iyz="0" izz="0.001"/>
    </inertial>
  </link>

  <joint name="right_ankle_joint" type="revolute">
    <parent link="right_shin"/>
    <child link="right_foot"/>
    <origin xyz="0 0 -0.28" rpy="0 0 0"/>
    <axis xyz="0 1 0"/>
    <limit lower="-0.5" upper="0.5" effort="50" velocity="2.0"/>
  </joint>

</robot>
